Workbook

Sheet 概要
A1: 『あなたはだんだん眠くなる』製作費 概算見積もり（第320稿ベース）
A2: FILMOQ株式会社 2026-09-29作成 金額は円・税抜。青字＝入力値（変更可）、黄色＝早坂さんが決める前提。
A4: 前提 | B4: A ミニマム（ホン・サンス型） | C4: B 標準 | D4: C 余裕 | E4: メモ
A5: 撮影日数（日） | B5: =香盤!K17 | C5: =香盤!L17 | D5: =香盤!M17 | E5: 香盤シートの場ごとの日数の合計
A6: 準備日数（ロケハン・衣装合わせ・美術） | B6: 3 | C6: 5 | D6: 8 | E6: スタッフが拘束される撮影前の日数
A7: 本読み・リハーサル日数 | B7: 3 | C7: 10 | D7: 20 | E7: 濱口型に寄せるほど増やす
A8: 現場の人数（食事・交通の対象） | B8: 10 | C8: 16 | D8: 24 | E8: スタッフ＋その日の出演者の平均
A9: 予備費率 | B9: 0.1 | C9: 0.1 | D9: 0.1 | E9: 天候・夜明けの撮り直し・想定外
A11: 集計
A12: 小計（見積もりシート） | B12: =見積もり!J41 | C12: =見積もり!K41 | D12: =見積もり!L41
A13: 予備費 | B13: =B12*B9 | C13: =C12*C9 | D13: =D12*D9
A14: 合計（税抜） | B14: =B12+B13 | C14: =C12+C13 | D14: =D12+D13
A15: 消費税10%（参考） | B15: =B14*0.1 | C15: =C14*0.1 | D15: =D14*0.1
A16: 合計（税込・参考） | B16: =B14+B15 | C16: =C14+C15 | D16: =D14+D15
A18: 読み方
A19: A：スタッフ6人前後、自然光と画に映る明かり中心、編集・整音の一部を自社で。ホン・サンス、初期の濱口に近い組み方。
A20: B：スタッフ10〜12人、照明部と録音部を立てる。夜と夜明けの長回しを安全に撮れる最低ライン。
A21: C：スタッフ15人以上、美術・看板を作り込み、映画祭の渡航まで含む。製作費3,000万円の目標を超えるので、Cから削って3,000万円に収める使い方を想定。
A22: 監督・脚本・プロデューサー（早坂）の報酬は0で計上。自社の持ち出しとして別管理。
A23: 単価は相場の推測を含む（根拠シート参照）。実際に3社以上から見積もりを取ってから確定すること。
A24: 法務（子役の就労時間・ロケ許可・出演契約）と税務（助成金・消費税の扱い）は専門家に確認。

Sheet 撮影スケジュールA
A1: ミニマム（ホン・サンス型）撮影スケジュール案 順撮り・13撮影日＋休み3日＝16日間
A2: 物語の順に撮る（倉田の疲れが画に溜まっていく）。夜と夜明けが続くので、3〜4日ごとに休みを入れる。
A4: 日 | B4: 撮る場 | C4: 場所 | D4: 時間帯 | E4: 撮影日数 | F4: 出演 | G4: ねらい・注意
A5: 1日目 | B5: 1 | C5: L1 布団屋 | D5: 昼 | E5: 1 | F5: 倉田・アベ・店長・客の男 | G5: 実演のマットレスで倉田が本当に眠る。商店街の許可
A6: 2日目 | B6: 2 | C6: L2 アパート204号室 | D6: 夜〜朝 | E6: 1 | F6: 倉田・ミオ・真壁 | G6: 九平米。看板の照り返しだけで撮る
A7: 3日目 | B7: 3・4 | C7: L2 アパート前→204号室 | D7: 夜→朝 | E7: 1.5 | F7: 倉田・ミオ | G7: 3場は植え込みの陰から一カット。そのまま朝の4場へ
A8: 休み | E8: 0
A9: 4日目 | B9: 5 | C9: L3 雑居ビル（エレベーター・白い部屋） | D9: 深夜 | E9: 1 | F9: 倉田・ミオ・真壁・アベ・受講生 | G9: 4:3からスコープへの切り替えは編集で
A10: 5日目 | B10: 6・7 | C10: L3 給湯室・白い部屋 | D10: 深夜 | E10: 1 | F10: 倉田・ミオ・真壁・アベ | G10: 7場は給湯室の一カット
A11: 6日目 | B11: 8 | C11: L3 給湯室の奥 | D11: 昼〜夕 | E11: 1 | F11: 倉田・ミオ・アベ・コールセンターの女 | G11: 唯一の昼の雑居ビル。体を休める日にもなる
A12: 休み | E12: 0
A13: 7日目 | B13: 9 | C13: L3 白い部屋 | D13: 夜〜未明 | E13: 1 | F13: 倉田・ミオ・真壁・アベ・コールセンターの女
A14: 8日目 | B14: 10 | C14: L4 非常階段・九階の踊り場 | D14: 夜明け | E14: 1 | F14: 倉田・ミオ | G14: 夜明けは約20分で1テイク
A15: 9日目 | B15: 11 | C15: L4 非常階段〜駐車場 | D15: 夜明け | E15: 1 | F15: 倉田・ミオ | G15: 約10分の一カット（1回目）
A16: 10日目 | B16: 11 | C16: L4 非常階段〜駐車場 | D16: 夜明け | E16: 1 | F16: 倉田・ミオ | G16: 同（予備・2回目）。良ければ11日目を前倒し
A17: 休み | E17: 0
A18: 11日目 | B18: 12 | C18: L5 団地 | D18: 昼 | E18: 1 | F18: 倉田・ミオ・アベ・男の子 | G18: 子役は昼のみ、21時まで
A19: 12日目 | B19: 13 | C19: L3 白い部屋 | D19: 夜〜夜明け | E19: 1 | F19: 倉田・ミオ・真壁・受講生 | G19: 真壁の語り〜入眠の一カット
A20: 13日目 | B20: 13 | C20: L3 白い部屋 | D20: 夜明け〜朝 | E20: 0.5 | F20: 倉田・ミオ・真壁 | G20: 結末の一カット（ミオが起きる〜4:3に閉じる）。残り半日は予備
A21: 撮影日数の合計 | E21: =SUM(E5:E20)
A22: 香盤シートのAの合計 | E22: =香盤!K17
A24: L3（白い部屋・給湯室）は4〜7日目と12〜13日目の2回に分かれる。1か月借りれば続けて押さえられる（見積もりの前提）。
A25: L3とL4が同じビルなら、8〜10日目も同じ物件で済む。物件探しの第一条件にする。
A26: 俳優を本当に寝不足にして撮ることはしない。疲れは撮る順番と休みの置き方で作る。俳優の健康と安全、労働時間の問題になるため（確信度 高）。

Sheet スタッフ機材A
A1: ミニマム（ホン・サンス型）スタッフと機材
A3: 役割 | B3: 人数 | C3: 担当 | D3: メモ
A4: 監督・脚本 | B4: 1 | C4: 早坂 | D4: 現場で台詞を直す。撮影当日の朝に、その日の場を読み直す時間を取る
A5: 撮影（照明を兼ねる） | B5: 1 | C5: 未定 | D5: ズームで寄る。画に映る明かり（看板・蛍光灯・誘導灯）を主にする
A6: 撮影助手 | B6: 1 | C6: 未定 | D6: ピント・記録媒体・機材の管理
A7: 録音 | B7: 1 | C7: 未定 | D7: ガンマイク＋ピンマイク。会話劇なので一番削れない所
A8: 助監督・制作進行 | B8: 1 | C8: 未定 | D8: スケジュール・許可・食事・移動を一人で回す
A9: 美術・衣装・メイク | B9: 1 | C9: 未定 | D9: 白い部屋の塗り、小道具、衣装、メイクを兼ねる
A10: 合計 | B10: 6 | D10: ホン・サンスの組み方に近い最小の人数（確信度 中）
A12: 機材 | B12: 中身 | C12: メモ
A13: カメラ | B13: Sony FX6級＋ズームレンズ1本＋単焦点1本 | C13: FX6本体は1日約8,500〜22,000円（確信度 高）
A14: 三脚 | B14: 重めのビデオ三脚1台 | C14: 固定の長回しが多い。台本の「長いレンズで、動かない」に合わせる
A15: 照明 | B15: 小型LED 2〜3灯、電球、延長コード | C15: 主役は現場の明かり。白い部屋の蛍光灯は美術で作る
A16: 録音 | B16: ガンマイク、ピンマイク2本、録音機 | C16: 長回しでも台詞を落とさない
A17: 記録・編集 | B17: 記録媒体、ハードディスク、自社の編集機 | C17: 編集は自社（見積もりAの前提）
A18: 車両 | B18: 機材車1台（レンタル） | C18: L3とL4が同じビルなら移動が減る

Sheet 香盤
A1: 場 | B1: 場所（まとめ案） | C1: 時間帯 | D1: 倉田 | E1: ミオ | F1: 真壁 | G1: アベ | H1: 脇役・子ども | I1: 台本行数 | J1: 推定分数 | K1: 撮影日A | L1: 撮影日B | M1: 撮影日C | N1: メモ
A2: 1 | B2: L1 布団屋（商店街） | C2: 昼 | D2: 1 | E2: 0 | F2: 0 | G2: 1 | H2: 店長・客の男 | I2: 203 | J2: =I2/$I$15*102 | K2: 1 | L2: 1.5 | M2: 2
A3: 2 | B3: L2 アパート204号室 | C3: 夜〜朝 | D3: 1 | E3: 1 | F3: 1 | G3: 0 | I3: 271 | J3: =I3/$I$15*102 | K3: 1 | L3: 1.5 | M3: 2
A4: 3 | B4: L2 アパート前・コインランドリー看板 | C4: 夜 | D4: 1 | E4: 1 | F4: 0 | G4: 0 | I4: 219 | J4: =I4/$I$15*102 | K4: 1 | L4: 1.5 | M4: 2 | N4: 一カット。看板の三色が要
A5: 4 | B5: L2 アパート204号室 | C5: 朝 | D5: 1 | E5: 1 | F5: 0 | G5: 0 | I5: 72 | J5: =I5/$I$15*102 | K5: 0.5 | L5: 0.5 | M5: 1
A6: 5 | B6: L3 雑居ビル（エレベーター・白い部屋） | C6: 深夜 | D6: 1 | E6: 1 | F6: 1 | G6: 1 | H6: コールセンターの女・受講生 | I6: 203 | J6: =I6/$I$15*102 | K6: 1 | L6: 1.5 | M6: 2 | N6: 4:3からスコープへ
A7: 6 | B7: L3 雑居ビル（給湯室・白い部屋） | C7: 深夜 | D7: 1 | E7: 1 | F7: 1 | G7: 1 | H7: 受講生 | I7: 103 | J7: =I7/$I$15*102 | K7: 0.5 | L7: 1 | M7: 1.5
A8: 7 | B8: L3 雑居ビル（給湯室） | C8: 深夜 | D8: 1 | E8: 1 | F8: 1 | G8: 0 | I8: 124 | J8: =I8/$I$15*102 | K8: 0.5 | L8: 1 | M8: 1.5 | N8: 一カット
A9: 8 | B9: L3 雑居ビル（給湯室の奥） | C9: 昼〜夕 | D9: 1 | E9: 1 | F9: 0 | G9: 1 | H9: コールセンターの女 | I9: 225 | J9: =I9/$I$15*102 | K9: 1 | L9: 1.5 | M9: 2
A10: 9 | B10: L3 雑居ビル（白い部屋） | C10: 夜〜未明 | D10: 1 | E10: 1 | F10: 1 | G10: 1 | H10: コールセンターの女 | I10: 221 | J10: =I10/$I$15*102 | K10: 1 | L10: 1.5 | M10: 2
A11: 10 | B11: L4 非常階段・九階の踊り場 | C11: 夜明け | D11: 1 | E11: 1 | F11: 0 | G11: 0 | I11: 107 | J11: =I11/$I$15*102 | K11: 1 | L11: 1 | M11: 1.5 | N11: 一カット。夜明けは1日1テイク
A12: 11 | B12: L4 非常階段〜駐車場 | C12: 夜明け | D12: 1 | E12: 1 | F12: 0 | G12: 0 | I12: 199 | J12: =I12/$I$15*102 | K12: 2 | L12: 2 | M12: 3 | N12: 約10分の一カット。撮り直し日を含む
A13: 12 | B13: L5 団地 | C13: 昼 | D13: 1 | E13: 1 | F13: 0 | G13: 1 | H13: 男の子（子役・昼のみ） | I13: 156 | J13: =I13/$I$15*102 | K13: 1 | L13: 1 | M13: 1.5 | N13: 子役は21時まで（演劇子役の特例）
A14: 13 | B14: L3 雑居ビル（白い部屋） | C14: 夜〜朝 | D14: 1 | E14: 1 | F14: 1 | G14: 0 | H14: 受講生（エキストラ） | I14: 313 | J14: =I14/$I$15*102 | K14: 1.5 | L14: 2.5 | M14: 3 | N14: 語り〜入眠の一カット＋結末の一カット
A15: 合計 | I15: =SUM(I2:I14) | J15: =SUM(J2:J14)
A16: 出演日数（その俳優が出る場の撮影日の合計）
A17: 撮影日数の合計 | K17: =SUM(K2:K14) | L17: =SUM(L2:L14) | M17: =SUM(M2:M14)
A19: 俳優別の出演日数
A20: 俳優 | K20: A | L20: B | M20: C
A21: 倉田 | K21: =SUMPRODUCT(D2:D14,K2:K14) | L21: =SUMPRODUCT(D2:D14,L2:L14) | M21: =SUMPRODUCT(D2:D14,M2:M14)
A22: ミオ | K22: =SUMPRODUCT(E2:E14,K2:K14) | L22: =SUMPRODUCT(E2:E14,L2:L14) | M22: =SUMPRODUCT(E2:E14,M2:M14)
A23: 真壁 | K23: =SUMPRODUCT(F2:F14,K2:K14) | L23: =SUMPRODUCT(F2:F14,L2:L14) | M23: =SUMPRODUCT(F2:F14,M2:M14)
A24: アベ | K24: =SUMPRODUCT(G2:G14,K2:K14) | L24: =SUMPRODUCT(G2:G14,L2:L14) | M24: =SUMPRODUCT(G2:G14,M2:M14)
A26: 場所のまとめ案：8か所→5か所（L1〜L5）。L3とL4を同じ雑居ビルで借りられれば、移動と借り賃が大きく減る。
A27: 撮影順：倉田の声を睡眠で作るなら、L3は5〜9場と13場で2回に分けて借りる（順撮り）。場所でまとめるなら1回で済むが、芝居の作り方が変わる。

Sheet 見積もり
A1: 区分 | B1: 項目 | C1: 単位 | D1: 数量A | E1: 数量B | F1: 数量C | G1: 単価A | H1: 単価B | I1: 単価C | J1: 金額A | K1: 金額B | L1: 金額C | M1: 根拠・確信度
A2: 出演 | B2: 倉田（主演） | C2: 日 | D2: =香盤!K21 | E2: =香盤!L21 | F2: =香盤!M21 | G2: 50000 | H2: 80000 | I2: 120000 | J2: =D2*G2 | K2: =E2*H2 | L2: =F2*I2 | M2: 推測・確信度 低。俳優と事務所で大きく変わる
A3: 出演 | B3: ミオ（主演） | C3: 日 | D3: =香盤!K22 | E3: =香盤!L22 | F3: =香盤!M22 | G3: 50000 | H3: 80000 | I3: 120000 | J3: =D3*G3 | K3: =E3*H3 | L3: =F3*I3 | M3: 推測・確信度 低
A4: 出演 | B4: 真壁 | C4: 日 | D4: =香盤!K23 | E4: =香盤!L23 | F4: =香盤!M23 | G4: 40000 | H4: 60000 | I4: 100000 | J4: =D4*G4 | K4: =E4*H4 | L4: =F4*I4 | M4: 推測・確信度 低
A5: 出演 | B5: アベさん | C5: 日 | D5: =香盤!K24 | E5: =香盤!L24 | F5: =香盤!M24 | G5: 30000 | H5: 50000 | I5: 80000 | J5: =D5*G5 | K5: =E5*H5 | L5: =F5*I5 | M5: 推測・確信度 低
A6: 出演 | B6: 脇役（店長・客の男・コールセンターの女） | C6: 人日 | D6: 6 | E6: 8 | F6: 10 | G6: 20000 | H6: 30000 | I6: 50000 | J6: =D6*G6 | K6: =E6*H6 | L6: =F6*I6 | M6: 推測・確信度 低
A7: 出演 | B7: 子役（男の子）＋付き添い | C7: 日 | D7: 1 | E7: 1 | F7: 1.5 | G7: 30000 | H7: 50000 | I7: 80000 | J7: =D7*G7 | K7: =E7*H7 | L7: =F7*I7 | M7: 昼のみ。就労は21時まで（演劇子役の特例）
A8: 出演 | B8: 受講生エキストラ | C8: 人日 | D8: 6 | E8: 10 | F8: 15 | G8: 5000 | H8: 10000 | I8: 15000 | J8: =D8*G8 | K8: =E8*H8 | L8: =F8*I8 | M8: 推測・確信度 中
A9: 出演 | B9: 本読み・リハーサル（主演4人） | C9: 人日 | D9: =概要!B7*4 | E9: =概要!C7*4 | F9: =概要!D7*4 | G9: 10000 | H9: 15000 | I9: 20000 | J9: =D9*G9 | K9: =E9*H9 | L9: =F9*I9 | M9: 推測・確信度 低
A10: スタッフ | B10: 撮影技師 | C10: 日 | D10: =概要!B5+概要!B6 | E10: =概要!C5+概要!C6 | F10: =概要!D5+概要!D6 | G10: 30000 | H10: 40000 | I10: 50000 | J10: =D10*G10 | K10: =E10*H10 | L10: =F10*I10 | M10: カメラマン日当の相場 約2万円/日を下限の目安に（確信度 中）
A11: スタッフ | B11: 撮影助手 | C11: 人日 | D11: =概要!B5*1 | E11: =概要!C5*1 | F11: =概要!D5*2 | G11: 15000 | H11: 20000 | I11: 25000 | J11: =D11*G11 | K11: =E11*H11 | L11: =F11*I11 | M11: 推測・確信度 中
A12: スタッフ | B12: 照明技師＋助手 | C12: 人日 | D12: =概要!B5*0 | E12: =概要!C5*2 | F12: =概要!D5*3 | G12: 0 | H12: 30000 | I12: 35000 | J12: =D12*G12 | K12: =E12*H12 | L12: =F12*I12 | M12: A は撮影部が兼ねる。推測・確信度 中
A13: スタッフ | B13: 録音技師 | C13: 日 | D13: =概要!B5+概要!B6 | E13: =概要!C5+概要!C6 | F13: =概要!D5+概要!D6 | G13: 25000 | H13: 30000 | I13: 40000 | J13: =D13*G13 | K13: =E13*H13 | L13: =F13*I13 | M13: 推測・確信度 中
A14: スタッフ | B14: 助監督・制作進行 | C14: 人日 | D14: =概要!B5+概要!B6*1 | E14: =概要!C5+概要!C6*2 | F14: =概要!D5+概要!D6*3 | G14: 20000 | H14: 25000 | I14: 30000 | J14: =D14*G14 | K14: =E14*H14 | L14: =F14*I14 | M14: 推測・確信度 中
A15: スタッフ | B15: 美術・衣装・メイク | C15: 人日 | D15: =概要!B5+概要!B6*1 | E15: =概要!C5+概要!C6*2 | F15: =概要!D5+概要!D6*3 | G15: 20000 | H15: 25000 | I15: 30000 | J15: =D15*G15 | K15: =E15*H15 | L15: =F15*I15 | M15: 推測・確信度 中
A16: 機材 | B16: カメラ一式（FX6級＋レンズ） | C16: 日 | D16: =概要!B5 | E16: =概要!C5 | F16: =概要!D5 | G16: 20000 | H16: 40000 | I16: 80000 | J16: =D16*G16 | K16: =E16*H16 | L16: =F16*I16 | M16: FX6本体のレンタル 約8,500〜22,000円/日（確信度 高）＋レンズ・記録媒体
A17: 機材 | B17: 照明機材 | C17: 日 | D17: =概要!B5 | E17: =概要!C5 | F17: =概要!D5 | G17: 10000 | H17: 30000 | I17: 60000 | J17: =D17*G17 | K17: =E17*H17 | L17: =F17*I17 | M17: 推測・確信度 中
A18: 機材 | B18: 録音機材 | C18: 日 | D18: =概要!B5 | E18: =概要!C5 | F18: =概要!D5 | G18: 5000 | H18: 10000 | I18: 15000 | J18: =D18*G18 | K18: =E18*H18 | L18: =F18*I18 | M18: 推測・確信度 中
A19: 機材 | B19: 車両（機材車） | C19: 日 | D19: =概要!B5 | E19: =概要!C5 | F19: =概要!D5 | G19: 10000 | H19: 20000 | I19: 30000 | J19: =D19*G19 | K19: =E19*H19 | L19: =F19*I19 | M19: 推測・確信度 中
A20: 場所 | B20: L1 布団屋 | C20: 日 | D20: =香盤!K2 | E20: =香盤!L2 | F20: =香盤!M2 | G20: 50000 | H20: 80000 | I20: 100000 | J20: =D20*G20 | K20: =E20*H20 | L20: =F20*I20 | M20: 推測・確信度 低
A21: 場所 | B21: L2 アパート（204号室・建物前） | C21: 日 | D21: =香盤!K3+香盤!K4+香盤!K5 | E21: =香盤!L3+香盤!L4+香盤!L5 | F21: =香盤!M3+香盤!M4+香盤!M5 | G21: 30000 | H21: 50000 | I21: 80000 | J21: =D21*G21 | K21: =E21*H21 | L21: =F21*I21 | M21: 推測・確信度 低
A22: 場所 | B22: L3 雑居ビル（空き物件・月借り） | C22: 月 | D22: 1 | E22: 1 | F22: 1.5 | G22: 300000 | H22: 500000 | I22: 800000 | J22: =D22*G22 | K22: =E22*H22 | L22: =F22*I22 | M22: 空きテナントの月額を想定。推測・確信度 低
A23: 場所 | B23: L3 白く塗る・原状回復 | C23: 式 | D23: 1 | E23: 1 | F23: 1 | G23: 200000 | H23: 400000 | I23: 600000 | J23: =D23*G23 | K23: =E23*H23 | L23: =F23*I23 | M23: 推測・確信度 低
A24: 場所 | B24: L4 非常階段・駐車場 | C24: 日 | D24: =香盤!K11+香盤!K12 | E24: =香盤!L11+香盤!L12 | F24: =香盤!M11+香盤!M12 | G24: 50000 | H24: 80000 | I24: 100000 | J24: =D24*G24 | K24: =E24*H24 | L24: =F24*I24 | M24: L3と同じビルなら0にできる。推測・確信度 低
A25: 場所 | B25: L5 団地（撮影許可） | C25: 日 | D25: =香盤!K13 | E25: =香盤!L13 | F25: =香盤!M13 | G25: 30000 | H25: 50000 | I25: 80000 | J25: =D25*G25 | K25: =E25*H25 | L25: =F25*I25 | M25: 推測・確信度 低
A26: 美術 | B26: コインランドリー看板（赤・緑・青） | C26: 式 | D26: 1 | E26: 1 | F26: 1 | G26: 100000 | H26: 300000 | I26: 500000 | J26: =D26*G26 | K26: =E26*H26 | L26: =F26*I26 | M26: 実在の看板が使えれば減る。推測・確信度 低
A27: 美術 | B27: 小道具・衣装・配信画面の作り込み | C27: 式 | D27: 1 | E27: 1 | F27: 1 | G27: 150000 | H27: 300000 | I27: 600000 | J27: =D27*G27 | K27: =E27*H27 | L27: =F27*I27 | M27: 名刺・ロゴ・手帳・犬のアイコンなど。推測・確信度 低
A28: 制作費 | B28: 食事（1人1日3,000円） | C28: 人日 | D28: =概要!B8*概要!B5 | E28: =概要!C8*概要!C5 | F28: =概要!D8*概要!D5 | G28: 3000 | H28: 3000 | I28: 3500 | J28: =D28*G28 | K28: =E28*H28 | L28: =F28*I28 | M28: 推測・確信度 中
A29: 制作費 | B29: 交通・駐車 | C29: 人日 | D29: =概要!B8*概要!B5 | E29: =概要!C8*概要!C5 | F29: =概要!D8*概要!D5 | G29: 1000 | H29: 1500 | I29: 2000 | J29: =D29*G29 | K29: =E29*H29 | L29: =F29*I29 | M29: 推測・確信度 中
A30: 制作費 | B30: 撮影保険 | C30: 式 | D30: 1 | E30: 1 | F30: 1 | G30: 50000 | H30: 100000 | I30: 200000 | J30: =D30*G30 | K30: =E30*H30 | L30: =F30*I30 | M30: 推測・確信度 低。保険会社に要見積もり
A31: 制作費 | B31: 試し撮り（3場を一晩） | C31: 式 | D31: 1 | E31: 1 | F31: 1 | G31: 50000 | H31: 100000 | I31: 200000 | J31: =D31*G31 | K31: =E31*H31 | L31: =F31*I31 | M31: 撮影前に一晩で試す費用
A32: 仕上げ | B32: 編集 | C32: 式 | D32: 1 | E32: 1 | F32: 1 | G32: 0 | H32: 500000 | I32: 1000000 | J32: =D32*G32 | K32: =E32*H32 | L32: =F32*I32 | M32: A は自社（早坂）で編集
A33: 仕上げ | B33: カラーグレーディング | C33: 式 | D33: 1 | E33: 1 | F33: 1 | G33: 200000 | H33: 600000 | I33: 1500000 | J33: =D33*G33 | K33: =E33*H33 | L33: =F33*I33 | M33: 推測・確信度 低
A34: 仕上げ | B34: 整音・MA | C34: 式 | D34: 1 | E34: 1 | F34: 1 | G34: 300000 | H34: 800000 | I34: 1500000 | J34: =D34*G34 | K34: =E34*H34 | L34: =F34*I34 | M34: 推測・確信度 低
A35: 仕上げ | B35: 音楽 | C35: 式 | D35: 1 | E35: 1 | F35: 1 | G35: 100000 | H35: 500000 | I35: 1000000 | J35: =D35*G35 | K35: =E35*H35 | L35: =F35*I35 | M35: 推測・確信度 低
A36: 仕上げ | B36: 英語字幕 | C36: 式 | D36: 1 | E36: 1 | F36: 1 | G36: 150000 | H36: 250000 | I36: 400000 | J36: =D36*G36 | K36: =E36*H36 | L36: =F36*I36 | M36: 推測・確信度 低
A37: 仕上げ | B37: DCP作成 | C37: 式 | D37: 1 | E37: 1 | F37: 1 | G37: 100000 | H37: 200000 | I37: 300000 | J37: =D37*G37 | K37: =E37*H37 | L37: =F37*I37 | M37: 推測・確信度 低
A38: 映画祭 | B38: 応募料・素材送付 | C38: 式 | D38: 1 | E38: 1 | F38: 1 | G38: 100000 | H38: 200000 | I38: 400000 | J38: =D38*G38 | K38: =E38*H38 | L38: =F38*I38 | M38: 推測・確信度 低
A39: 映画祭 | B39: 渡航（監督・主演） | C39: 式 | D39: 0 | E39: 1 | F39: 1 | G39: 0 | H39: 500000 | I39: 1000000 | J39: =D39*G39 | K39: =E39*H39 | L39: =F39*I39 | M39: 選ばれた場合のみ
A41: 小計（税抜） | J41: =SUM(J2:J39) | K41: =SUM(K2:K39) | L41: =SUM(L2:L39)
...

Sheet 根拠
A1: 項目 | B1: 内容 | C1: 出典 | D1: 確信度
A2: カメラのレンタル | B2: Sony FX6 本体 1日 約8,470円（税込）〜22,000円（税抜） | C2: 東京カメラ機材レンタル http://tokyo-camera.jp/sony-fx6/ ／ ティスマン https://www.tisman.co.jp/item/fx6/ ／ TREE https://www.tdsi.co.jp/crank/equipment/digital_camera/sony/fx6.html | D2: 高
A3: カメラマンの日当 | B3: 日当制で1撮影 約2万円が相場（拘束時間に関わらず） | C3: PRONIアイミツ https://imitsu.jp/cost/movie/article/video | D3: 中
A4: 映画スタッフの報酬 | B4: 決まった規定はなく、約40年ほぼ変わらない「相場」がある | C4: 内閣官房 資料 https://www.cas.go.jp/jp/seisaku/atarashii_sihonsyugi/wgkaisai/contents_dai1/siryou9.pdf | D4: 中
A5: 低予算映画の規模 | B5: インディーズ・新人監督作は数百万〜3,000万円程度。『カメラを止めるな！』は約300万円 | C5: LOOHCS https://loohcs.jp/articles/1740 ／ 映画チャンネル https://eigachannel.jp/movie/122198/ | D5: 中
A6: 子役の就労時間 | B6: 15歳未満は20時〜翌5時の就労禁止。演劇子役（映画を含む）は21時〜翌6時の禁止に緩和 | C6: 骨董通り法律事務所 https://www.kottolaw.com/column/000893.html ／ 厚労省福岡労働局 https://jsite.mhlw.go.jp/fukuoka-roudoukyoku/var/rev0/0119/7561/6.pdf | D6: 高（最終確認は社労士へ）
A7: 俳優のギャラ | B7: 公開された相場の資料は見つからず。事務所・知名度で大きく変わる | C7: — | D7: 低（要見積もり）
A8: ロケ・物件 | B8: 空きテナントの月額、団地・商店街の許可料は地域と管理者で大きく変わる | C8: — | D8: 低（要見積もり）
